File: 04_XRD/Richard_SnO_on_si_wafer.csv
[Measurement conditions]
Sample identification,
Comment - 1,"Configuration=Factory configuration, Owner=User-1, Creation date=13/01/2009 10:38:05"
Comment - 2,"Goniometer=PW3050/65 (Theta/2Theta); Minimum step size 2Theta:0.0001; Minimum step size Omega:0.0001"
Comment - 3,"Sample stage=MRD Cradle; Minimum step size Phi:0.01; Minimum step size Psi:0.01; Minimum step size X:0.01; Minimum step size Y:0.01; Minimum step size Z:0.001"
Comment - 4,"Diffractometer system=XPERT-PRO"
Comment - 5,"Measurement program=Richard, Owner=User-1, Creation date=18/11/2022 16:09:50"
Comment - 6,"Batch program=Richard batch, Owner=User-1, Creation date=18/11/2022 16:11:36"
Anode material,Cu
K-Alpha1 wavelength,1.5405980
K-Alpha2 wavelength,1.5444260
Ratio K-Alpha2/K-Alpha1,0.500
Receiving slit,0.76
Monochromator used,NO
Generator voltage, 45
Tube current, 40
File date and time,02/Dec/2022 09:52
Unit cell,
h k l, 0 0 0
Scan axis,2Theta-Omega
Scan range,15.003800004,44.999930836
Scan step size,0.0098477
Omega offset,0.00000000
No. of points, 3046
Scan type,CONTINUOUS
Phi,0.00
Psi,0.00
X,0.00
Y,0.00
Z,9.451
Time per step,149.970
[Scan points]
Angle,Intensity
15.008723860,7423.0
15.038266996,7545.0
15.067810132,7607.0
15.097353268,7474.0
15.126896404,7486.0
15.156439540,7402.0
15.185982676,7472.0
15.215525813,7271.0
15.245068949,7531.0
15.274612085,7607.0
15.304155221,7367.0
15.333698357,7292.0
15.363241493,7292.0
15.392784629,7279.0
15.422327765,7442.0
15.451870901,7302.0
15.481414037,7437.0
15.510957173,7334.0
15.540500309,7155.0
15.570043445,7367.0
15.599586582,7416.0
15.629129718,7198.0
15.658672854,7196.0
15.688215990,7250.0
15.717759126,7236.0
15.747302262,7316.0
15.776845398,7145.0
15.806388534,7174.0
15.835931670,7232.0
15.865474806,7242.0
15.895017942,7287.0
15.924561078,7226.0
15.954104215,7031.0
15.983647351,7174.0
16.013190487,7098.0
16.042733623,7065.0
16.072276759,7234.0
16.101819895,7065.0
16.131363031,7125.0
16.160906167,7179.0
16.190449303,7180.0
16.219992439,7036.0
16.249535575,6920.0
16.279078711,6920.0
16.308621847,7032.0
16.338164984,6988.0
16.367708120,7058.0
16.397251256,7016.0
16.426794392,7068.0
16.456337528,6768.0
16.485880664,7077.0
16.515423800,6932.0
16.544966936,6810.0
16.574510072,6889.0
16.604053208,6859.0
16.633596344,6855.0
16.663139480,6936.0
16.692682616,6998.0
16.722225753,6910.0
16.751768889,6782.0
16.781312025,6951.0
16.810855161,6929.0
16.840398297,6721.0
16.869941433,7060.0
16.899484569,6863.0
16.929027705,6705.0
16.958570841,6789.0
16.988113977,6872.0
17.017657113,6859.0
17.047200249,6815.0
17.076743386,6870.0
17.106286522,6806.0
17.135829658,6716.0
17.165372794,6738.0
17.194915930,6815.0
17.224459066,6683.0
17.254002202,6766.0
17.283545338,6722.0
17.313088474,6671.0
17.342631610,6756.0
17.372174746,6685.0
17.401717882,6783.0
17.431261018,6977.0
17.460804155,6764.0
17.490347291,6759.0
17.519890427,6838.0
17.549433563,6805.0
17.578976699,6672.0
17.608519835,6866.0
17.638062971,6785.0
17.667606107,6744.0
17.697149243,6673.0
17.726692379,6871.0
17.756235515,6643.0
17.785778651,6749.0
17.815321787,6749.0
17.844864924,6769.0
17.874408060,7015.0
17.903951196,7121.0
17.933494332,7133.0
17.963037468,7213.0
17.992580604,7365.0
18.022123740,7668.0
18.051666876,7947.0
18.081210012,8274.0
18.110753148,8362.0
18.140296284,8883.0
18.169839420,9432.0
18.199382557,9695.0
18.228925693,10801.0
18.258468829,11519.0
18.288011965,12465.0
18.317555101,13369.0
18.347098237,12192.0
18.376641373,10427.0
18.406184509,8935.0
18.435727645,7977.0
18.465270781,7652.0
18.494813917,7332.0
18.524357053,7244.0
18.553900189,7097.0
18.583443326,6907.0
18.612986462,7009.0
18.642529598,6883.0
18.672072734,6773.0
18.701615870,6954.0
18.731159006,6936.0
18.760702142,6837.0
18.790245278,6849.0
18.819788414,6910.0
18.849331550,6704.0
18.878874686,6902.0
18.908417822,6831.0
18.937960958,6852.0
18.967504095,6869.0
18.997047231,6696.0
19.026590367,6701.0
19.056133503,6659.0
19.085676639,6773.0
19.115219775,6738.0
19.144762911,6778.0
19.174306047,6694.0
19.203849183,6685.0
19.233392319,6731.0
19.262935455,6780.0
19.292478591,6736.0
19.322021728,6699.0
19.351564864,6724.0
19.381108000,6751.0
19.410651136,6652.0
19.440194272,6619.0
19.469737408,6638.0
19.499280544,6649.0
19.528823680,6554.0
19.558366816,6676.0
19.587909952,6739.0
19.617453088,6562.0
19.646996224,6583.0
19.676539360,6716.0
19.706082497,6674.0
19.735625633,6449.0
19.765168769,6674.0
19.794711905,6687.0
19.824255041,6686.0
19.853798177,6662.0
19.883341313,6578.0
19.912884449,6518.0
19.942427585,6746.0
19.971970721,6727.0
20.001513857,6734.0
20.031056993,6547.0
20.060600129,6532.0
20.090143266,6603.0
20.119686402,6652.0
20.149229538,6687.0
20.178772674,6590.0
20.208315810,6631.0
20.237858946,6539.0
20.267402082,6665.0
20.296945218,6596.0
20.326488354,6660.0
20.356031490,6742.0
20.385574626,6689.0
20.415117762,6535.0
20.444660899,6626.0
20.474204035,6602.0
20.503747171,6464.0
20.533290307,6471.0
20.562833443,6587.0
20.592376579,6632.0
20.621919715,6549.0
20.651462851,6442.0
20.681005987,6430.0
20.710549123,6459.0
20.740092259,6556.0
20.769635395,6535.0
20.799178531,6533.0
20.828721668,6517.0
20.858264804,6407.0
20.887807940,6447.0
20.917351076,6359.0
20.946894212,6392.0
20.976437348,6667.0
21.005980484,6418.0
21.035523620,6480.0
21.065066756,6457.0
21.094609892,6495.0
21.124153028,6376.0
21.153696164,6426.0
21.183239300,6345.0
21.212782437,6508.0
21.242325573,6365.0
21.271868709,6371.0
21.301411845,6387.0
21.330954981,6514.0
21.360498117,6363.0
21.390041253,6483.0
21.419584389,6304.0
21.449127525,6236.0
21.478670661,6358.0
21.508213797,6452.0
21.537756933,6274.0
21.567300069,6386.0
21.596843206,6367.0
21.626386342,6377.0
21.655929478,6319.0
21.685472614,6500.0
21.715015750,6389.0
21.744558886,6357.0
21.774102022,6220.0
21.803645158,6218.0
21.833188294,6332.0
21.862731430,6189.0
21.892274566,6197.0
21.921817702,6411.0
21.951360839,6108.0
21.980903975,6183.0
22.010447111,6373.0
22.039990247,6314.0
22.069533383,6200.0
22.099076519,6394.0
22.128619655,6148.0
22.158162791,6317.0
22.187705927,6343.0
22.217249063,6331.0
22.246792199,6427.0
22.276335335,6248.0
22.305878471,6268.0
22.335421608,6352.0
22.364964744,6269.0
22.394507880,6103.0
22.424051016,6195.0
22.453594152,6374.0
22.483137288,6334.0
22.512680424,6158.0
22.542223560,6284.0
22.571766696,6273.0
22.601309832,6171.0
22.630852968,6278.0
22.660396104,6287.0
22.689939240,6170.0
22.719482377,6263.0
22.749025513,6248.0
22.778568649,6330.0
22.808111785,6272.0
22.837654921,6213.0
22.867198057,6196.0
22.896741193,6106.0
22.926284329,6227.0
22.955827465,6297.0
22.985370601,6294.0
23.014913737,6171.0
23.044456873,6199.0
23.074000010,6137.0
23.103543146,6224.0
23.133086282,6161.0
23.162629418,6190.0
23.192172554,6240.0
23.221715690,6244.0
23.251258826,6059.0
23.280801962,6113.0
23.310345098,6277.0
23.339888234,6198.0
23.369431370,6188.0
23.398974506,6261.0
23.428517642,6181.0
23.458060779,6220.0
23.487603915,6123.0
23.517147051,6212.0
23.546690187,6126.0
23.576233323,6165.0
23.605776459,6283.0
23.635319595,6229.0
23.664862731,6171.0
23.694405867,6416.0
23.723949003,6361.0
23.753492139,6240.0
23.783035275,6267.0
23.812578411,6227.0
23.842121548,5907.0
23.871664684,6195.0
23.901207820,6148.0
23.930750956,6142.0
23.960294092,6311.0
23.989837228,6292.0
24.019380364,6259.0
24.048923500,6082.0
24.078466636,6266.0
24.108009772,6262.0
24.137552908,6181.0
24.167096044,6133.0
24.196639181,6296.0
24.226182317,6404.0
24.255725453,6274.0
24.285268589,6005.0
24.314811725,6137.0
24.344354861,6264.0
24.373897997,6290.0
24.403441133,6066.0
24.432984269,6298.0
24.462527405,6167.0
24.492070541,6271.0
24.521613677,6114.0
24.551156813,6148.0
24.580699950,6249.0
24.610243086,6156.0
24.639786222,6274.0
24.669329358,6268.0
24.698872494,6082.0
24.728415630,6278.0
24.757958766,6282.0
24.787501902,6293.0
24.817045038,6194.0
24.846588174,6274.0
24.876131310,6168.0
24.905674446,6231.0
24.935217582,6127.0
24.964760719,6346.0
24.994303855,6253.0
25.023846991,6244.0
25.053390127,6249.0
25.082933263,6086.0
25.112476399,6307.0
25.142019535,6255.0
25.171562671,6197.0
25.201105807,6203.0
25.230648943,6355.0
25.260192079,6216.0
25.289735215,6211.0
25.319278352,6266.0
25.348821488,6204.0
25.378364624,6223.0
25.407907760,6195.0
25.437450896,6091.0
25.466994032,6266.0
25.496537168,6188.0
25.526080304,6091.0
25.555623440,6348.0
25.585166576,6317.0
25.614709712,6136.0
25.644252848,6324.0
25.673795984,6227.0
25.703339121,6180.0
25.732882257,6017.0
25.762425393,6171.0
25.791968529,6148.0
25.821511665,6082.0
25.851054801,6111.0
25.880597937,6189.0
25.910141073,6125.0
25.939684209,6126.0
25.969227345,6150.0
25.998770481,6186.0
26.028313617,6187.0
26.057856753,6186.0
26.087399890,6197.0
26.116943026,5982.0
26.146486162,6330.0
26.176029298,6117.0
26.205572434,6228.0
26.235115570,6070.0
26.264658706,6260.0
26.294201842,6178.0
26.323744978,6360.0
26.353288114,6249.0
26.382831250,6287.0
26.412374386,6271.0
26.441917523,6192.0
26.471460659,6310.0
26.501003795,6148.0
26.530546931,6304.0
26.560090067,6322.0
26.589633203,6152.0
26.619176339,6248.0
26.648719475,6283.0
26.678262611,6285.0
26.707805747,6233.0
26.737348883,6382.0
26.766892019,6531.0
26.796435155,6397.0
26.825978292,6194.0
26.855521428,6254.0
26.885064564,6320.0
26.914607700,6364.0
26.944150836,6232.0
26.973693972,6269.0
27.003237108,6345.0
27.032780244,6134.0
27.062323380,6292.0
27.091866516,6164.0
27.121409652,6237.0
27.150952788,6138.0
27.180495924,6257.0
27.210039061,6159.0
27.239582197,6269.0
27.269125333,6247.0
27.298668469,6136.0
27.328211605,6234.0
27.357754741,6178.0
27.387297877,6105.0
27.416841013,6251.0
27.446384149,6236.0
27.475927285,6225.0
27.505470421,6191.0
27.535013557,6214.0
27.564556693,6199.0
27.594099830,6151.0
27.623642966,6131.0
27.653186102,6325.0
27.682729238,6332.0
27.712272374,6087.0
27.741815510,6157.0
27.771358646,6171.0
27.800901782,6294.0
27.830444918,6245.0
27.859988054,6327.0
27.889531190,6280.0
27.919074326,6303.0
27.948617463,6150.0
27.978160599,6169.0
28.007703735,6228.0
28.037246871,6201.0
28.066790007,6151.0
28.096333143,6331.0
28.125876279,6268.0
28.155419415,6172.0
28.184962551,6218.0
28.214505687,6211.0
28.244048823,6267.0
28.273591959,6400.0
28.303135095,6099.0
28.332678232,6164.0
28.362221368,6114.0
28.391764504,6287.0
28.421307640,6435.0
28.450850776,6293.0
28.480393912,6490.0
28.509937048,6304.0
28.539480184,6352.0
28.569023320,6448.0
28.598566456,6311.0
28.628109592,6255.0
28.657652728,6381.0
28.687195864,6231.0
28.716739001,6359.0
28.746282137,6465.0
28.775825273,6473.0
28.805368409,6544.0
28.834911545,6433.0
28.864454681,6554.0
28.893997817,6672.0
28.923540953,6668.0
28.953084089,6568.0
28.982627225,6786.0
29.012170361,6580.0
29.041713497,6709.0
29.071256634,6637.0
29.100799770,6952.0
29.130342906,6767.0
29.159886042,6931.0
29.189429178,6825.0
29.218972314,7038.0
29.248515450,7202.0
29.278058586,7194.0
29.307601722,7116.0
29.337144858,7411.0
29.366687994,7702.0
29.396231130,7811.0
29.425774266,8068.0
29.455317403,8400.0
29.484860539,8964.0
29.514403675,9758.0
29.543946811,10493.0
29.573489947,11725.0
29.603033083,13201.0
29.632576219,15004.0
29.662119355,17517.0
29.691662491,20558.0
29.721205627,24778.0
29.750748763,29440.0
29.780291899,35163.0
29.809835035,40792.0
29.839378172,45434.0
29.868921308,45640.0
29.898464444,40207.0
29.928007580,33998.0
29.957550716,27591.0
29.987093852,21278.0
30.016636988,16790.0
30.046180124,13865.0
30.075723260,11713.0
30.105266396,10562.0
30.134809532,9658.0
30.164352668,8821.0
30.193895805,8585.0
30.223438941,8043.0
30.252982077,7776.0
30.282525213,7703.0
30.312068349,7404.0
30.341611485,7205.0
30.371154621,7057.0
30.400697757,6972.0
30.430240893,6798.0
30.459784029,6815.0
30.489327165,6737.0
30.518870301,6762.0
30.548413437,6789.0
30.577956574,6673.0
30.607499710,6506.0
30.637042846,6605.0
30.666585982,6723.0
30.696129118,6426.0
30.725672254,6580.0
30.755215390,6526.0
30.784758526,6607.0
30.814301662,6635.0
30.843844798,6373.0
30.873387934,6364.0
30.902931070,6561.0
30.932474206,6456.0
30.962017343,6396.0
30.991560479,6471.0
31.021103615,6470.0
31.050646751,6393.0
31.080189887,6397.0
31.109733023,6387.0
31.139276159,6279.0
31.168819295,6362.0
31.198362431,6433.0
31.227905567,6345.0
31.257448703,6279.0
31.286991839,6473.0
31.316534976,6512.0
31.346078112,6445.0
31.375621248,6353.0
31.405164384,6405.0
31.434707520,6383.0
31.464250656,6366.0
31.493793792,6549.0
31.523336928,6200.0
31.552880064,6377.0
31.582423200,6193.0
31.611966336,6402.0
31.641509472,6450.0
31.671052608,6192.0
31.700595745,6078.0
31.730138881,6387.0
31.759682017,6323.0
31.789225153,6266.0
31.818768289,6204.0
31.848311425,6293.0
31.877854561,6363.0
31.907397697,6176.0
31.936940833,6165.0
31.966483969,6106.0
31.996027105,6197.0
32.025570241,6318.0
32.055113377,6364.0
32.084656514,6271.0
32.114199650,6341.0
32.143742786,6417.0
32.173285922,6379.0
32.202829058,6455.0
32.232372194,6328.0
32.261915330,6409.0
32.291458466,6181.0
32.321001602,6378.0
32.350544738,6245.0
32.380087874,6210.0
32.409631010,6270.0
32.439174147,6232.0
32.468717283,6326.0
32.498260419,6228.0
32.527803555,6216.0
32.557346691,6251.0
32.586889827,6337.0
32.616432963,6279.0
32.645976099,6327.0
32.675519235,6277.0
32.705062371,6272.0
32.734605507,6240.0
32.764148643,6284.0
32.793691779,6270.0
32.823234916,6403.0
32.852778052,6200.0
32.882321188,6376.0
32.911864324,6653.0
32.941407460,8298.0
32.970950596,12680.0
33.000493732,7188.0
33.030036868,8252.0
33.059580004,9536.0
33.089123140,7266.0
33.118666276,7060.0
33.148209412,7698.0
33.177752548,8550.0
33.207295685,9708.0
33.236838821,11657.0
33.266381957,14754.0
33.295925093,17598.0
33.325468229,16300.0
33.355011365,13635.0
33.384554501,12865.0
33.414097637,10582.0
33.443640773,8469.0
33.473183909,7243.0
33.502727045,6797.0
33.532270181,6425.0
33.561813317,6284.0
33.591356454,6290.0
33.620899590,6407.0
33.650442726,6128.0
33.679985862,6340.0
33.709528998,6170.0
33.739072134,6056.0
33.768615270,6068.0
33.798158406,6012.0
33.827701542,6016.0
33.857244678,5869.0
33.886787814,5897.0
33.916330950,6074.0
33.945874087,6028.0
33.975417223,6057.0
34.004960359,6044.0
34.034503495,5857.0
34.064046631,5835.0
34.093589767,5893.0
34.123132903,5865.0
34.152676039,5774.0
34.182219175,5923.0
34.211762311,5776.0
34.241305447,5914.0
34.270848583,5841.0
34.300391719,5802.0
34.329934856,5834.0
34.359477992,5761.0
34.389021128,5880.0
34.418564264,5876.0
34.448107400,5916.0
34.477650536,5760.0
34.507193672,5787.0
34.536736808,5782.0
34.566279944,5725.0
34.595823080,5662.0
34.625366216,5748.0
34.654909352,5808.0
34.684452488,5711.0
34.713995625,5540.0
34.743538761,5462.0
34.773081897,5734.0
34.802625033,5511.0
34.832168169,5567.0
34.861711305,5656.0
34.891254441,5618.0
34.920797577,5529.0
34.950340713,5603.0
34.979883849,5655.0
35.009426985,5652.0
35.038970121,5595.0
35.068513258,5573.0
35.098056394,5494.0
35.127599530,5297.0
35.157142666,5542.0
35.186685802,5527.0
35.216228938,5450.0
35.245772074,5412.0
35.275315210,5499.0
35.304858346,5352.0
35.334401482,5388.0
35.363944618,5411.0
35.393487754,5297.0
35.423030890,5269.0
35.452574027,5430.0
35.482117163,5392.0
35.511660299,5310.0
35.541203435,5285.0
35.570746571,5256.0
35.600289707,5310.0
35.629832843,5443.0
35.659375979,5369.0
35.688919115,5211.0
35.718462251,5256.0
35.748005387,5305.0
35.777548523,5251.0
35.807091659,5233.0
35.836634796,5349.0
35.866177932,5262.0
35.895721068,5333.0
35.925264204,5305.0
35.954807340,5345.0
35.984350476,5192.0
36.013893612,5427.0
36.043436748,5309.0
36.072979884,5230.0
36.102523020,5235.0
36.132066156,5333.0
36.161609292,5362.0
36.191152429,5276.0
36.220695565,5306.0
36.250238701,5155.0
36.279781837,5159.0
36.309324973,5284.0
36.338868109,5234.0
36.368411245,5353.0
36.397954381,5231.0
36.427497517,5236.0
36.457040653,5250.0
36.486583789,5333.0
36.516126925,5419.0
36.545670061,5365.0
36.575213198,5491.0
36.604756334,5556.0
36.634299470,5677.0
36.663842606,5741.0
36.693385742,5853.0
36.722928878,5863.0
36.752472014,6206.0
36.782015150,6391.0
36.811558286,6503.0
36.841101422,6798.0
36.870644558,7113.0
36.900187694,7360.0
36.929730830,8182.0
36.959273967,8800.0
36.988817103,9336.0
37.018360239,9988.0
37.047903375,10963.0
37.077446511,12417.0
37.106989647,13751.0
37.136532783,14630.0
37.166075919,13428.0
37.195619055,11631.0
37.225162191,10679.0
37.254705327,9219.0
37.284248463,7803.0
37.313791600,6878.0
37.343334736,6259.0
37.372877872,5770.0
37.402421008,5555.0
37.431964144,5277.0
37.461507280,5302.0
37.491050416,5163.0
37.520593552,5013.0
37.550136688,5045.0
37.579679824,5007.0
37.609222960,4855.0
37.638766096,4758.0
37.668309232,4738.0
37.697852369,4653.0
37.727395505,4713.0
37.756938641,4671.0
37.786481777,4632.0
37.816024913,4490.0
37.845568049,4673.0
37.875111185,4642.0
37.904654321,4415.0
37.934197457,4386.0
37.963740593,4495.0
37.993283729,4499.0
38.022826865,4407.0
38.052370001,4478.0
38.081913138,4401.0
38.111456274,4422.0
38.140999410,4283.0
38.170542546,4454.0
38.200085682,4378.0
38.229628818,4333.0
38.259171954,4379.0
38.288715090,4361.0
38.318258226,4443.0
38.347801362,4450.0
38.377344498,4331.0
38.406887634,4412.0
38.436430771,4237.0
38.465973907,4159.0
38.495517043,4291.0
38.525060179,4250.0
38.554603315,4129.0
38.584146451,4248.0
38.613689587,4134.0
38.643232723,4182.0
38.672775859,4182.0
38.702318995,4120.0
38.731862131,4137.0
38.761405267,4070.0
38.790948403,4147.0
38.820491540,4101.0
38.850034676,4180.0
38.879577812,4014.0
38.909120948,4088.0
38.938664084,3978.0
38.968207220,3979.0
38.997750356,4081.0
39.027293492,4003.0
39.056836628,4065.0
39.086379764,4074.0
39.115922900,4081.0
39.145466036,3958.0
39.175009172,4023.0
39.204552309,4094.0
39.234095445,3982.0
39.263638581,4017.0
39.293181717,3863.0
39.322724853,3833.0
39.352267989,3924.0
39.381811125,3874.0
39.411354261,3814.0
39.440897397,4014.0
39.470440533,3939.0
39.499983669,3885.0
39.529526805,3892.0
39.559069941,3825.0
39.588613078,3825.0
39.618156214,3872.0
39.647699350,3817.0
39.677242486,3851.0
39.706785622,3744.0
39.736328758,3888.0
39.765871894,3748.0
39.795415030,3809.0
39.824958166,3883.0
39.854501302,3824.0
39.884044438,3642.0
39.913587574,3750.0
39.943130711,3844.0
39.972673847,3698.0
40.002216983,3668.0
40.031760119,3737.0
40.061303255,3639.0
40.090846391,3661.0
40.120389527,3552.0
40.149932663,3640.0
40.179475799,3582.0
40.209018935,3630.0
40.238562071,3581.0
40.268105207,3680.0
40.297648343,3505.0
40.327191480,3559.0
40.356734616,3523.0
40.386277752,3503.0
40.415820888,3587.0
40.445364024,3681.0
40.474907160,3620.0
40.504450296,3446.0
40.533993432,3638.0
40.563536568,3422.0
40.593079704,3444.0
40.622622840,3623.0
40.652165976,3537.0
40.681709112,3524.0
40.711252249,3393.0
40.740795385,3515.0
40.770338521,3501.0
40.799881657,3465.0
40.829424793,3365.0
40.858967929,3429.0
40.888511065,3505.0
40.918054201,3393.0
40.947597337,3438.0
40.977140473,3469.0
41.006683609,3438.0
41.036226745,3434.0
41.065769882,3282.0
41.095313018,3373.0
41.124856154,3341.0
41.154399290,3356.0
41.183942426,3331.0
41.213485562,3367.0
41.243028698,3344.0
41.272571834,3353.0
41.302114970,3306.0
41.331658106,3367.0
41.361201242,3320.0
41.390744378,3281.0
41.420287514,3340.0
41.449830651,3295.0
41.479373787,3243.0
41.508916923,3275.0
41.538460059,3284.0
41.568003195,3183.0
41.597546331,3129.0
41.627089467,3301.0
41.656632603,3273.0
41.686175739,3242.0
41.715718875,3209.0
41.745262011,3242.0
41.774805147,3143.0
41.804348283,3078.0
41.833891420,3172.0
41.863434556,3172.0
41.892977692,3128.0
41.922520828,3165.0
41.952063964,3218.0
41.981607100,3132.0
42.011150236,3141.0
42.040693372,3142.0
42.070236508,3141.0
42.099779644,3156.0
42.129322780,3138.0
42.158865916,3052.0
42.188409053,3001.0
42.217952189,3088.0
42.247495325,3011.0
42.277038461,3047.0
42.306581597,3063.0
42.336124733,3168.0
42.365667869,2953.0
42.395211005,3115.0
42.424754141,3050.0
42.454297277,3043.0
42.483840413,3055.0
42.513383549,3003.0
42.542926685,2994.0
42.572469822,3065.0
42.602012958,2937.0
42.631556094,3017.0
42.661099230,3061.0
42.690642366,2924.0
42.720185502,2928.0
42.749728638,2842.0
42.779271774,2860.0
42.808814910,2855.0
42.838358046,3040.0
42.867901182,2866.0
42.897444318,3031.0
42.926987454,2892.0
42.956530591,2899.0
42.986073727,2807.0
43.015616863,2874.0
43.045159999,2865.0
43.074703135,2968.0
43.104246271,2829.0
43.133789407,2874.0
43.163332543,2835.0
43.192875679,2815.0
43.222418815,2842.0
43.251961951,2865.0
43.281505087,2886.0
43.311048224,2831.0
43.340591360,2869.0
43.370134496,2832.0
43.399677632,2808.0
43.429220768,2847.0
43.458763904,2869.0
43.488307040,2855.0
43.517850176,2890.0
43.547393312,2768.0
43.576936448,2755.0
43.606479584,2744.0
43.636022720,2845.0
43.665565856,2779.0
43.695108993,2740.0
43.724652129,2801.0
43.754195265,2638.0
43.783738401,2781.0
43.813281537,2763.0
43.842824673,2797.0
43.872367809,2712.0
43.901910945,2736.0
43.931454081,2791.0
43.960997217,2760.0
43.990540353,2737.0
44.020083489,2732.0
44.049626625,2741.0
44.079169762,2759.0
44.108712898,2808.0
44.138256034,2785.0
44.167799170,2819.0
44.197342306,2807.0
44.226885442,2833.0
44.256428578,2969.0
44.285971714,2935.0
44.315514850,2948.0
44.345057986,2900.0
44.374601122,2953.0
44.404144258,2787.0
44.433687395,2888.0
44.463230531,2778.0
44.492773667,2901.0
44.522316803,2765.0
44.551859939,2828.0
44.581403075,2724.0
44.610946211,2674.0
44.640489347,2600.0
44.670032483,2532.0
44.699575619,2595.0
44.729118755,2609.0
44.758661891,2677.0
44.788205027,2573.0
44.817748164,2559.0
44.847291300,2574.0
44.876834436,2632.0
44.906377572,2524.0
44.935920708,2465.0
44.965463844,2596.0
44.995006980,2516.0